<?xml version="1.0" ?>
<!-- =================================================================================== -->
<!-- |    This document was autogenerated by xacro from hsr_co605_gripper_onhand_kinect2.xacro | -->
<!-- |    EDITING THIS FILE BY HAND IS NOT RECOMMENDED                                 | -->
<!-- =================================================================================== -->
<robot name="hsr_co602_gripper_onhand_kinect2" xmlns:xacro="http://ros.org/wiki/xacro">
  <link name="world"/>
  <joint name="fixed" type="fixed">
    <parent link="world"/>
    <child link="base_link"/>
    <origin rpy="0 0 0" xyz="0 0 1"/>
  </joint>
  <joint name="fixed2" type="fixed">
    <parent link="world"/>
    <child link="base_link2"/>
    <origin rpy="0 0 0" xyz="0 1 1"/>
  </joint>
  <link name="base_link">
    <inertial>
      <origin rpy="0 0 0" xyz="-0.021912 3.5206E-07 0.072666"/>
      <mass value="3.5836"/>
      <inertia ixx="2.9136E-05" ixy="-2.1811E-09" ixz="-0.00010967" iyy="0.00060536" iyz="-4.5389E-10" izz="0.000578"/>
    </inertial>
    <visual>
      <origin rpy="0 0 0" xyz="0 0 0"/>
      <geometry>
        <mesh filename="package://hsr_description/meshes/co605/base_link.STL"/>
      </geometry>
      <material name="">
        <color rgba="0.4 0.5 0.6 1"/>
      </material>
    </visual>
    <collision>
      <origin rpy="0 0 0" xyz="0 0 0"/>
      <geometry>
        <mesh filename="package://hsr_description/meshes/co605/base_link.STL"/>
      </geometry>
    </collision>
  </link>
  <link name="base_link2">
    <inertial>
      <origin rpy="0 0 0" xyz="-0.021912 3.5206E-07 0.072666"/>
      <mass value="3.5836"/>
      <inertia ixx="2.9136E-05" ixy="-2.1811E-09" ixz="-0.00010967" iyy="0.00060536" iyz="-4.5389E-10" izz="0.000578"/>
    </inertial>
    <visual>
      <origin rpy="0 0 0" xyz="0 0 0"/>
      <geometry>
        <mesh filename="package://hsr_description/meshes/co605/base_link.STL"/>
      </geometry>
      <material name="">
        <color rgba="0.4 0.5 0.6 1"/>
      </material>
    </visual>
    <collision>
      <origin rpy="0 0 0" xyz="0 0 0"/>
      <geometry>
        <mesh filename="package://hsr_description/meshes/co605/base_link.STL"/>
      </geometry>
    </collision>
  </link>
  <!--  -->
  <link name="link1">
    <inertial>
      <origin rpy="0 0 0" xyz="6.6053E-07 -0.041864 0.057461"/>
      <mass value="2.2858"/>
      <inertia ixx="0.0028736" ixy="-1.2977E-08" ixz="-1.1421E-08" iyy="0.0012558" iyz="-0.0014242" izz="0.001619"/>
    </inertial>
    <visual>
      <origin rpy="0 0 0" xyz="0 0 0"/>
      <geometry>
        <mesh filename="package://hsr_description/meshes/co605/link1.STL"/>
      </geometry>
      <material name="">
        <color rgba="0.6 0.5 0.4 1"/>
      </material>
    </visual>
    <collision>
      <origin rpy="0 0 0" xyz="0 0 0"/>
      <geometry>
        <mesh filename="package://hsr_description/meshes/co605/link1.STL"/>
      </geometry>
    </collision>
  </link>
  <joint name="joint_1" type="revolute">
    <origin rpy="-3.1416 5.9903E-29 -1.4937E-16" xyz="0 0 0.3215"/>
    <parent link="base_link"/>
    <child link="link1"/>
    <axis xyz="0 0 -1"/>
    <limit effort="28" lower="-3.490658503988" upper="3.490658503988" velocity="3.2"/>
    <safety_controller k_position="100" k_velocity="10" soft_lower_limit="-3.481931857728" soft_upper_limit="3.481931857728"/>
  </joint>
  <link name="link2">
    <inertial>
      <origin rpy="0 0 0" xyz="1.0568E-05 -0.1934 0.0072764"/>
      <mass value="3.9796"/>
      <inertia ixx="0.024928" ixy="-9.3143E-07" ixz="4.2908E-07" iyy="0.0049988" iyz="0.0099684" izz="0.019932"/>
    </inertial>
    <visual>
      <origin rpy="0 0 0" xyz="0 0 0"/>
      <geometry>
        <mesh filename="package://hsr_description/meshes/co605/link2.STL"/>
      </geometry>
      <material name="">
        <color rgba="0.4 0.5 0.6 1"/>
      </material>
    </visual>
    <collision>
      <origin rpy="0 0 0" xyz="0 0 0"/>
      <geometry>
        <mesh filename="package://hsr_description/meshes/co605/link2.STL"/>
      </geometry>
    </collision>
  </link>
  <joint name="joint_2" type="revolute">
    <origin rpy="1.5708 -1.5708 0" xyz="0 0 0"/>
    <parent link="link1"/>
    <child link="link2"/>
    <axis xyz="0 0 1"/>
    <limit effort="28" lower="-2.268928027592" upper="1" velocity="3.2"/>
    <safety_controller k_position="100" k_velocity="10" soft_lower_limit="-2.260201381332" soft_upper_limit="1"/>
  </joint>
  <link name="link3">
    <inertial>
      <origin rpy="0 0 0" xyz="-4.1646E-06 -0.084864 -0.023661"/>
      <mass value="2.3017"/>
      <inertia ixx="0.0050619" ixy="1.9871E-07" ixz="-9.377E-08" iyy="0.00080339" iyz="0.0014584" izz="0.0043189"/>
    </inertial>
    <visual>
      <origin rpy="0 0 0" xyz="0 0 0"/>
      <geometry>
        <mesh filename="package://hsr_description/meshes/co605/link3.STL"/>
      </geometry>
      <material name="">
        <color rgba="0.6 0.5 0.4 1"/>
      </material>
    </visual>
    <collision>
      <origin rpy="0 0 0" xyz="0 0 0"/>
      <geometry>
        <mesh filename="package://hsr_description/meshes/co605/link3.STL"/>
      </geometry>
    </collision>
  </link>
  <joint name="joint_3" type="revolute">
    <origin rpy="-7.0321E-15 1.0327E-14 -1.5708" xyz="0 -0.4 0"/>
    <parent link="link2"/>
    <child link="link3"/>
    <axis xyz="0 0 1"/>
    <limit effort="28" lower="1" upper="3.665191429188" velocity="3.2"/>
    <safety_controller k_position="100" k_velocity="10" soft_lower_limit="0.008726646259" soft_upper_limit="3.656464782928"/>
  </joint>
  <link name="link4">
    <inertial>
      <origin rpy="0 0 0" xyz="0.058545 -4.4729E-06 0.33207"/>
      <mass value="1.1696"/>
      <inertia ixx="0.00052342" ixy="-2.9755E-08" ixz="-0.0004967" iyy="0.00099547" iyz="-3.1299E-08" izz="0.00047263"/>
    </inertial>
    <visual>
      <origin rpy="0 0 0" xyz="0 0 0"/>
      <geometry>
        <mesh filename="package://hsr_description/meshes/co605/link4.STL"/>
      </geometry>
      <material name="">
        <color rgba="0.4 0.5 0.6 1"/>
      </material>
    </visual>
    <collision>
      <origin rpy="0 0 0" xyz="0 0 0"/>
      <geometry>
        <mesh filename="package://hsr_description/meshes/co605/link4.STL"/>
      </geometry>
    </collision>
  </link>
  <joint name="joint_4" type="revolute">
    <origin rpy="1.5708 1.5708 0" xyz="0 0 0"/>
    <parent link="link3"/>
    <child link="link4"/>
    <axis xyz="0 0 1"/>
    <limit effort="28" lower="-3.0" upper="3.0" velocity="3.2"/>
    <safety_controller k_position="100" k_velocity="10" soft_lower_limit="-3.0" soft_upper_limit="3.0"/>
  </joint>
  <link name="link5">
    <inertial>
      <origin rpy="0 0 0" xyz="-1.4755E-07 -0.034466 0.0044663"/>
      <mass value="1.4115"/>
      <inertia ixx="0.0015897" ixy="-6.782E-09" ixz="-1.3146E-08" iyy="0.0006121" iyz="-0.00040625" izz="0.00097818"/>
    </inertial>
    <visual>
      <origin rpy="0 0 0" xyz="0 0 0"/>
      <geometry>
        <mesh filename="package://hsr_description/meshes/co605/link5.STL"/>
      </geometry>
      <material name="">
        <color rgba="0.6 0.5 0.4 1"/>
      </material>
    </visual>
    <collision>
      <origin rpy="0 0 0" xyz="0 0 0"/>
      <geometry>
        <mesh filename="package://hsr_description/meshes/co605/link5.STL"/>
      </geometry>
    </collision>
  </link>
  <joint name="joint_5" type="revolute">
    <origin rpy="-1.5708 -3.2281E-16 1.5708" xyz="0 0 0.4"/>
    <parent link="link4"/>
    <child link="link5"/>
    <axis xyz="0 0 1"/>
    <limit effort="28" lower="-2.268928027592" upper="2.268928027592" velocity="3.2"/>
    <safety_controller k_position="100" k_velocity="10" soft_lower_limit="-2.260201381332" soft_upper_limit="2.260201381332"/>
  </joint>
  <link name="link6">
    <inertial>
      <origin rpy="0 0 0" xyz="-9.6295E-05 0.00016669 -0.035518"/>
      <mass value="0.30888"/>
      <inertia ixx="8.8278E-05" ixy="-1.1971E-06" ixz="3.4899E-07" iyy="8.9661E-05" iyz="-6.0395E-07" izz="5.5013E-06"/>
    </inertial>
    <visual>
      <origin rpy="0 0 0" xyz="0 0 0"/>
      <geometry>
        <mesh filename="package://hsr_description/meshes/co605/link6.STL"/>
      </geometry>
      <material name="">
        <color rgba="0.4 0.5 0.6 1"/>
      </material>
    </visual>
    <collision>
      <origin rpy="0 0 0" xyz="0 0 0"/>
      <geometry>
        <mesh filename="package://hsr_description/meshes/co605/link6.STL"/>
      </geometry>
    </collision>
  </link>
  <joint name="joint_6" type="revolute">
    <origin rpy="-1.5708 2.7756E-17 -3.1416" xyz="0 -0.205 0"/>
    <parent link="link5"/>
    <child link="link6"/>
    <axis xyz="0 0 1"/>
    <limit effort="28" lower="-5.1" upper="5.1" velocity="3.2"/>
    <safety_controller k_position="100" k_velocity="10" soft_lower_limit="-5.1" soft_upper_limit="5.1"/>
  </joint>
  <!--    -->
  <link name="R_link1">
    <inertial>
      <origin rpy="0 0 0" xyz="6.6053E-07 -0.041864 0.057461"/>
      <mass value="2.2858"/>
      <inertia ixx="0.0028736" ixy="-1.2977E-08" ixz="-1.1421E-08" iyy="0.0012558" iyz="-0.0014242" izz="0.001619"/>
    </inertial>
    <visual>
      <origin rpy="0 0 0" xyz="0 0 0"/>
      <geometry>
        <mesh filename="package://hsr_description/meshes/co605/link1.STL"/>
      </geometry>
      <material name="">
        <color rgba="0.6 0.5 0.4 1"/>
      </material>
    </visual>
    <collision>
      <origin rpy="0 0 0" xyz="0 0 0"/>
      <geometry>
        <mesh filename="package://hsr_description/meshes/co605/link1.STL"/>
      </geometry>
    </collision>
  </link>
  <joint name="R_joint_1" type="revolute">
    <origin rpy="-3.1416 5.9903E-29 -1.4937E-16" xyz="0 0 0.3215"/>
    <parent link="base_link2"/>
    <child link="R_link1"/>
    <axis xyz="0 0 -1"/>
    <limit effort="28" lower="-3.490658503988" upper="3.490658503988" velocity="3.2"/>
    <safety_controller k_position="100" k_velocity="10" soft_lower_limit="-3.481931857728" soft_upper_limit="3.481931857728"/>
  </joint>
  <link name="R_link2">
    <inertial>
      <origin rpy="0 0 0" xyz="1.0568E-05 -0.1934 0.0072764"/>
      <mass value="3.9796"/>
      <inertia ixx="0.024928" ixy="-9.3143E-07" ixz="4.2908E-07" iyy="0.0049988" iyz="0.0099684" izz="0.019932"/>
    </inertial>
    <visual>
      <origin rpy="0 0 0" xyz="0 0 0"/>
      <geometry>
        <mesh filename="package://hsr_description/meshes/co605/link2.STL"/>
      </geometry>
      <material name="">
        <color rgba="0.4 0.5 0.6 1"/>
      </material>
    </visual>
    <collision>
      <origin rpy="0 0 0" xyz="0 0 0"/>
      <geometry>
        <mesh filename="package://hsr_description/meshes/co605/link2.STL"/>
      </geometry>
    </collision>
  </link>
  <joint name="R_joint_2" type="revolute">
    <origin rpy="1.5708 -1.5708 0" xyz="0 0 0"/>
    <parent link="R_link1"/>
    <child link="R_link2"/>
    <axis xyz="0 0 1"/>
    <limit effort="28" lower="-2.268928027592" upper="1" velocity="3.2"/>
    <safety_controller k_position="100" k_velocity="10" soft_lower_limit="-2.260201381332" soft_upper_limit="1"/>
  </joint>
  <link name="R_link3">
    <inertial>
      <origin rpy="0 0 0" xyz="-4.1646E-06 -0.084864 -0.023661"/>
      <mass value="2.3017"/>
      <inertia ixx="0.0050619" ixy="1.9871E-07" ixz="-9.377E-08" iyy="0.00080339" iyz="0.0014584" izz="0.0043189"/>
    </inertial>
    <visual>
      <origin rpy="0 0 0" xyz="0 0 0"/>
      <geometry>
        <mesh filename="package://hsr_description/meshes/co605/link3.STL"/>
      </geometry>
      <material name="">
        <color rgba="0.6 0.5 0.4 1"/>
      </material>
    </visual>
    <collision>
      <origin rpy="0 0 0" xyz="0 0 0"/>
      <geometry>
        <mesh filename="package://hsr_description/meshes/co605/link3.STL"/>
      </geometry>
    </collision>
  </link>
  <joint name="R_joint_3" type="revolute">
    <origin rpy="-7.0321E-15 1.0327E-14 -1.5708" xyz="0 -0.4 0"/>
    <parent link="R_link2"/>
    <child link="R_link3"/>
    <axis xyz="0 0 1"/>
    <limit effort="28" lower="1" upper="3.665191429188" velocity="3.2"/>
    <safety_controller k_position="100" k_velocity="10" soft_lower_limit="0.008726646259" soft_upper_limit="3.656464782928"/>
  </joint>
  <link name="R_link4">
    <inertial>
      <origin rpy="0 0 0" xyz="0.058545 -4.4729E-06 0.33207"/>
      <mass value="1.1696"/>
      <inertia ixx="0.00052342" ixy="-2.9755E-08" ixz="-0.0004967" iyy="0.00099547" iyz="-3.1299E-08" izz="0.00047263"/>
    </inertial>
    <visual>
      <origin rpy="0 0 0" xyz="0 0 0"/>
      <geometry>
        <mesh filename="package://hsr_description/meshes/co605/link4.STL"/>
      </geometry>
      <material name="">
        <color rgba="0.4 0.5 0.6 1"/>
      </material>
    </visual>
    <collision>
      <origin rpy="0 0 0" xyz="0 0 0"/>
      <geometry>
        <mesh filename="package://hsr_description/meshes/co605/link4.STL"/>
      </geometry>
    </collision>
  </link>
  <joint name="R_joint_4" type="revolute">
    <origin rpy="1.5708 1.5708 0" xyz="0 0 0"/>
    <parent link="R_link3"/>
    <child link="R_link4"/>
    <axis xyz="0 0 1"/>
    <limit effort="28" lower="-3.0" upper="3.0" velocity="3.2"/>
    <safety_controller k_position="100" k_velocity="10" soft_lower_limit="-3.0" soft_upper_limit="3.0"/>
  </joint>
  <link name="R_link5">
    <inertial>
      <origin rpy="0 0 0" xyz="-1.4755E-07 -0.034466 0.0044663"/>
      <mass value="1.4115"/>
      <inertia ixx="0.0015897" ixy="-6.782E-09" ixz="-1.3146E-08" iyy="0.0006121" iyz="-0.00040625" izz="0.00097818"/>
    </inertial>
    <visual>
      <origin rpy="0 0 0" xyz="0 0 0"/>
      <geometry>
        <mesh filename="package://hsr_description/meshes/co605/link5.STL"/>
      </geometry>
      <material name="">
        <color rgba="0.6 0.5 0.4 1"/>
      </material>
    </visual>
    <collision>
      <origin rpy="0 0 0" xyz="0 0 0"/>
      <geometry>
        <mesh filename="package://hsr_description/meshes/co605/link5.STL"/>
      </geometry>
    </collision>
  </link>
  <joint name="R_joint_5" type="revolute">
    <origin rpy="-1.5708 -3.2281E-16 1.5708" xyz="0 0 0.4"/>
    <parent link="R_link4"/>
    <child link="R_link5"/>
    <axis xyz="0 0 1"/>
    <limit effort="28" lower="-2.268928027592" upper="2.268928027592" velocity="3.2"/>
    <safety_controller k_position="100" k_velocity="10" soft_lower_limit="-2.260201381332" soft_upper_limit="2.260201381332"/>
  </joint>
  <link name="R_link6">
    <inertial>
      <origin rpy="0 0 0" xyz="-9.6295E-05 0.00016669 -0.035518"/>
      <mass value="0.30888"/>
      <inertia ixx="8.8278E-05" ixy="-1.1971E-06" ixz="3.4899E-07" iyy="8.9661E-05" iyz="-6.0395E-07" izz="5.5013E-06"/>
    </inertial>
    <visual>
      <origin rpy="0 0 0" xyz="0 0 0"/>
      <geometry>
        <mesh filename="package://hsr_description/meshes/co605/link6.STL"/>
      </geometry>
      <material name="">
        <color rgba="0.4 0.5 0.6 1"/>
      </material>
    </visual>
    <collision>
      <origin rpy="0 0 0" xyz="0 0 0"/>
      <geometry>
        <mesh filename="package://hsr_description/meshes/co605/link6.STL"/>
      </geometry>
    </collision>
  </link>
  <joint name="R_joint_6" type="revolute">
    <origin rpy="-1.5708 2.7756E-17 -3.1416" xyz="0 -0.205 0"/>
    <parent link="R_link5"/>
    <child link="R_link6"/>
    <axis xyz="0 0 1"/>
    <limit effort="28" lower="-5.1" upper="5.1" velocity="3.2"/>
    <safety_controller k_position="100" k_velocity="10" soft_lower_limit="-5.1" soft_upper_limit="5.1"/>
  </joint>
  <!-- Size of square 'camera' box -->
  <link name="camera_link">
    <collision>
      <origin rpy="0 0 0" xyz="0 0 0"/>
      <geometry>
        <box size="0.05 0.05 0.05"/>
      </geometry>
    </collision>
    <visual>
      <origin rpy="0 0 0" xyz="0 0 0"/>
      <geometry>
        <box size="0.05 0.05 0.05"/>
      </geometry>
      <material name="red"/>
    </visual>
    <inertial>
      <mass value="1e-5"/>
      <origin rpy="0 0 0" xyz="0 0 0"/>
      <inertia ixx="1e-6" ixy="0" ixz="0" iyy="1e-6" iyz="0" izz="1e-6"/>
    </inertial>
  </link>
  <!-- kinect -->
  <gazebo reference="camera_link">
    <sensor name="openni_camera_camera" type="depth">
      <always_on>1</always_on>
      <visualize>true</visualize>
      <camera>
        <horizontal_fov>1.047</horizontal_fov>
        <image>
          <width>640</width>
          <height>480</height>
          <format>B8G8R8</format>
        </image>
        <depth_camera>

            </depth_camera>
        <clip>
          <near>0.1</near>
          <far>100</far>
        </clip>
      </camera>
      <plugin filename="libgazebo_ros_openni_kinect.so" name="camera_controller">
        <alwaysOn>true</alwaysOn>
        <baseline>0.2</baseline>
        <updateRate>30</updateRate>
        <cameraName>camera</cameraName>
        <frameName>kinect_frame</frameName>
        <imageTopicName>rgb/image_raw</imageTopicName>
        <depthImageTopicName>depth/image_raw</depthImageTopicName>
        <pointCloudTopicName>depth/points</pointCloudTopicName>
        <cameraInfoTopicName>rgb/camera_info</cameraInfoTopicName>
        <depthImageCameraInfoTopicName>depth/camera_info</depthImageCameraInfoTopicName>
        <pointCloudCutoff>0.5</pointCloudCutoff>
        <distortionK1>0</distortionK1>
        <distortionK2>0</distortionK2>
        <distortionK3>0</distortionK3>
        <distortionT1>0</distortionT1>
        <distortionT2>0</distortionT2>
        <CxPrime>0.0</CxPrime>
        <Cx>0.0</Cx>
        <Cy>0.0</Cy>
        <focalLength>0.0</focalLength>
      </plugin>
    </sensor>
  </gazebo>
  <link name="gripper_base_link_0">
    <inertial>
      <origin rpy="0 0 0" xyz="0.000131706391042187 -0.0390683856464977 0.081199520192839"/>
      <mass value="0.145677232438391"/>
      <inertia ixx="8.40495062422861E-05" ixy="-6.82136717259575E-07" ixz="9.08788702310012E-07" iyy="4.96036917958725E-05" iyz="3.95062698042515E-05" izz="3.44803015215572E-05"/>
    </inertial>
    <visual>
      <origin rpy="0 0 0" xyz="0 0 0"/>
      <geometry>
        <mesh filename="package://hsr_description/meshes/eye_hand_gripper/base_link.STL"/>
      </geometry>
      <material name="">
        <color rgba="0.4 0.4 0.35 1"/>
      </material>
    </visual>
    <collision>
      <origin rpy="0 0 0" xyz="0 0 0"/>
      <geometry>
        <mesh filename="package://hsr_description/meshes/eye_hand_gripper/base_link.STL"/>
      </geometry>
    </collision>
  </link>
  <link name="grisper_boby_link_0">
    <inertial>
      <origin rpy="0 0 0" xyz="2.84228059294067E-05 -0.000875529500481004 -0.00997402814116276"/>
      <mass value="0.0387962759306602"/>
      <inertia ixx="0" ixy="0" ixz="0" iyy="0" iyz="0" izz="0"/>
    </inertial>
    <visual>
      <origin rpy="0 0 0" xyz="0 0 0"/>
      <geometry>
        <mesh filename="package://hsr_description/meshes/eye_hand_gripper/grisper_boby_link.STL"/>
      </geometry>
      <material name="">
        <color rgba="0.4 0.55 0.35 1"/>
      </material>
    </visual>
    <collision>
      <origin rpy="0 0 0" xyz="0 0 0"/>
      <geometry>
        <mesh filename="package://hsr_description/meshes/eye_hand_gripper/grisper_boby_link.STL"/>
      </geometry>
    </collision>
  </link>
  <joint name="grisper_boby_joint_0" type="fixed">
    <origin rpy="1.5708 1.3479E-15 1.3852E-15" xyz="0 -0.01 0.064"/>
    <parent link="gripper_base_link_0"/>
    <child link="grisper_boby_link_0"/>
    <axis xyz="0 0 0"/>
  </joint>
  <link name="right_finger_1_link_0">
    <inertial>
      <origin rpy="0 0 0" xyz="-2.92388038200531E-06 0.0168231601122346 0.0089790044607883"/>
      <mass value="0.00235032514171626"/>
      <inertia ixx="0" ixy="0" ixz="0" iyy="0" iyz="0" izz="0"/>
    </inertial>
    <visual>
      <origin rpy="0 0 0" xyz="0 0 0"/>
      <geometry>
        <mesh filename="package://hsr_description/meshes/eye_hand_gripper/right_finger_1_link.STL"/>
      </geometry>
      <material name="">
        <color rgba="0.4 0.55 0.35 1"/>
      </material>
    </visual>
    <collision>
      <origin rpy="0 0 0" xyz="0 0 0"/>
      <geometry>
        <mesh filename="package://hsr_description/meshes/eye_hand_gripper/right_finger_1_link.STL"/>
      </geometry>
    </collision>
  </link>
  <joint name="right_finger_1_joint_0" type="continuous">
    <origin rpy="0 0 -0.501740656078991" xyz="0.04 0.036 -0.019"/>
    <parent link="grisper_boby_link_0"/>
    <child link="right_finger_1_link_0"/>
    <axis xyz="0 0 1"/>
  </joint>
  <link name="right_finger_2_link_0">
    <inertial>
      <origin rpy="0 0 0" xyz="-0.0085798133911776 0.00661394976740351 0.00600000756322747"/>
      <mass value="0.00200167864656235"/>
      <inertia ixx="0" ixy="0" ixz="0" iyy="0" iyz="0" izz="0"/>
    </inertial>
    <visual>
      <origin rpy="0 0 0" xyz="0 0 0"/>
      <geometry>
        <mesh filename="package://hsr_description/meshes/eye_hand_gripper/right_finger_2_link.STL"/>
      </geometry>
      <material name="">
        <color rgba="0.4 0.55 0.35 1"/>
      </material>
    </visual>
    <collision>
      <origin rpy="0 0 0" xyz="0 0 0"/>
      <geometry>
        <mesh filename="package://hsr_description/meshes/eye_hand_gripper/right_finger_2_link.STL"/>
      </geometry>
    </collision>
  </link>
  <joint name="right_finger_2_joint_0" type="continuous">
    <origin rpy="0 0 0.501740656078991" xyz="0 0.042 0.00300000000000001"/>
    <parent link="right_finger_1_link_0"/>
    <child link="right_finger_2_link_0"/>
    <axis xyz="0 0 1"/>
  </joint>
  <link name="right_finger_end_link_0">
    <inertial>
      <origin rpy="0 0 0" xyz="-0.0181096606742553 0.00899999232533871 0.000419374358405108"/>
      <mass value="0.00169081070175499"/>
      <inertia ixx="0" ixy="0" ixz="0" iyy="0" iyz="0" izz="0"/>
    </inertial>
    <visual>
      <origin rpy="0 0 0" xyz="0 0 0"/>
      <geometry>
        <mesh filename="package://hsr_description/meshes/eye_hand_gripper/right_finger_end_link.STL"/>
      </geometry>
      <material name="">
        <color rgba="0.4 0.55 0.35 1"/>
      </material>
    </visual>
    <collision>
      <origin rpy="0 0 0" xyz="0 0 0"/>
      <geometry>
        <mesh filename="package://hsr_description/meshes/eye_hand_gripper/right_finger_end_link.STL"/>
      </geometry>
    </collision>
  </link>
  <joint name="right_finger_end_joint_0" type="fixed">
    <origin rpy="1.5707963267949 0 -1.5707963267949" xyz="-0.0145 -0.0035 -0.00300000000000001"/>
    <parent link="right_finger_2_link_0"/>
    <child link="right_finger_end_link_0"/>
    <axis xyz="0 0 0"/>
  </joint>
  <link name="left_finger_1_link_0">
    <inertial>
      <origin rpy="0 0 0" xyz="-2.92395601426965E-06 0.0168231599777492 0.00897900452955606"/>
      <mass value="0.0023503251697047"/>
      <inertia ixx="0" ixy="0" ixz="0" iyy="0" iyz="0" izz="0"/>
    </inertial>
    <visual>
      <origin rpy="0 0 0" xyz="0 0 0"/>
      <geometry>
        <mesh filename="package://hsr_description/meshes/eye_hand_gripper/left_finger_1_link.STL"/>
      </geometry>
      <material name="">
        <color rgba="0.4 0.55 0.35 1"/>
      </material>
    </visual>
    <collision>
      <origin rpy="0 0 0" xyz="0 0 0"/>
      <geometry>
        <mesh filename="package://hsr_description/meshes/eye_hand_gripper/left_finger_1_link.STL"/>
      </geometry>
    </collision>
  </link>
  <joint name="left_finger_1_joint_0" type="continuous">
    <origin rpy="0 0 0.501740656078991" xyz="-0.04 0.036 -0.019"/>
    <parent link="grisper_boby_link_0"/>
    <child link="left_finger_1_link_0"/>
    <axis xyz="0 0 1"/>
  </joint>
  <link name="left_finger_2_link_0">
    <inertial>
      <origin rpy="0 0 0" xyz="-0.00857981339117761 0.00661394976740348 0.00600000756322748"/>
      <mass value="0.00200167864656235"/>
      <inertia ixx="0" ixy="0" ixz="0" iyy="0" iyz="0" izz="0"/>
    </inertial>
    <visual>
      <origin rpy="0 0 0" xyz="0 0 0"/>
      <geometry>
        <mesh filename="package://hsr_description/meshes/eye_hand_gripper/left_finger_2_link.STL"/>
      </geometry>
      <material name="">
        <color rgba="0.4 0.55 0.35 1"/>
      </material>
    </visual>
    <collision>
      <origin rpy="0 0 0" xyz="0 0 0"/>
      <geometry>
        <mesh filename="package://hsr_description/meshes/eye_hand_gripper/left_finger_2_link.STL"/>
      </geometry>
    </collision>
  </link>
  <joint name="left_finger_2_joint_0" type="continuous">
    <origin rpy="3.14159265358979 0 2.6398519975108" xyz="0 0.0419999999999999 0.0149999999999995"/>
    <parent link="left_finger_1_link_0"/>
    <child link="left_finger_2_link_0"/>
    <axis xyz="0 0 1"/>
  </joint>
  <link name="left_finger_end_link_0">
    <inertial>
      <origin rpy="0 0 0" xyz="-0.0181096606742553 0.00899999232533872 0.000419374358405097"/>
      <mass value="0.00169081070175499"/>
      <inertia ixx="0" ixy="0" ixz="0" iyy="0" iyz="0" izz="0"/>
    </inertial>
    <visual>
      <origin rpy="0 0 0" xyz="0 0 0"/>
      <geometry>
        <mesh filename="package://hsr_description/meshes/eye_hand_gripper/left_finger_end_link.STL"/>
      </geometry>
      <material name="">
        <color rgba="0.4 0.55 0.35 1"/>
      </material>
    </visual>
    <collision>
      <origin rpy="0 0 0" xyz="0 0 0"/>
      <geometry>
        <mesh filename="package://hsr_description/meshes/eye_hand_gripper/left_finger_end_link.STL"/>
      </geometry>
    </collision>
  </link>
  <joint name="left_finger_end_joint_0" type="fixed">
    <origin rpy="1.5707963267949 8.67361737988403E-17 -1.5707963267949" xyz="-0.0144999999999999 -0.0035 -0.00299999999999996"/>
    <parent link="left_finger_2_link_0"/>
    <child link="left_finger_end_link_0"/>
    <axis xyz="0 0 0"/>
  </joint>
  <link name="pick_gripper_link_0">
    <visual>
      <origin rpy="0 0 0" xyz="0 0 0"/>
      <geometry>
        <box size="0.001 0.0005 0.0005"/>
      </geometry>
    </visual>
  </link>
  <transmission name="tran1_0">
    <type>transmission_interface/SimpleTransmission</type>
    <joint name="right_finger_1_joint_0">
      <hardwareInterface>PositionJointInterface</hardwareInterface>
    </joint>
    <actuator name="right_finger_1_motor_0">
      <hardwareInterface>PositionJointInterface</hardwareInterface>
      <mechanicalReduction>1</mechanicalReduction>
    </actuator>
  </transmission>
  <transmission name="tran2_0">
    <type>transmission_interface/SimpleTransmission</type>
    <joint name="right_finger_2_joint_0">
      <hardwareInterface>PositionJointInterface</hardwareInterface>
    </joint>
    <actuator name="right_finger_2_motor_0">
      <hardwareInterface>PositionJointInterface</hardwareInterface>
      <mechanicalReduction>1</mechanicalReduction>
    </actuator>
  </transmission>
  <transmission name="tran3_0">
    <type>transmission_interface/SimpleTransmission</type>
    <joint name="left_finger_1_joint_0">
      <hardwareInterface>PositionJointInterface</hardwareInterface>
    </joint>
    <actuator name="left_finger_1_motor_0">
      <hardwareInterface>PositionJointInterface</hardwareInterface>
      <mechanicalReduction>1</mechanicalReduction>
    </actuator>
  </transmission>
  <transmission name="tran4_0">
    <type>transmission_interface/SimpleTransmission</type>
    <joint name="left_finger_2_joint_0">
      <hardwareInterface>PositionJointInterface</hardwareInterface>
    </joint>
    <actuator name="left_finger_2_motor_0">
      <hardwareInterface>PositionJointInterface</hardwareInterface>
      <mechanicalReduction>1</mechanicalReduction>
    </actuator>
  </transmission>
  <link name="gripper_base_link_1">
    <inertial>
      <origin rpy="0 0 0" xyz="0.000131706391042187 -0.0390683856464977 0.081199520192839"/>
      <mass value="0.145677232438391"/>
      <inertia ixx="8.40495062422861E-05" ixy="-6.82136717259575E-07" ixz="9.08788702310012E-07" iyy="4.96036917958725E-05" iyz="3.95062698042515E-05" izz="3.44803015215572E-05"/>
    </inertial>
    <visual>
      <origin rpy="0 0 0" xyz="0 0 0"/>
      <geometry>
        <mesh filename="package://hsr_description/meshes/eye_hand_gripper/base_link.STL"/>
      </geometry>
      <material name="">
        <color rgba="0.4 0.4 0.35 1"/>
      </material>
    </visual>
    <collision>
      <origin rpy="0 0 0" xyz="0 0 0"/>
      <geometry>
        <mesh filename="package://hsr_description/meshes/eye_hand_gripper/base_link.STL"/>
      </geometry>
    </collision>
  </link>
  <link name="grisper_boby_link_1">
    <inertial>
      <origin rpy="0 0 0" xyz="2.84228059294067E-05 -0.000875529500481004 -0.00997402814116276"/>
      <mass value="0.0387962759306602"/>
      <inertia ixx="0" ixy="0" ixz="0" iyy="0" iyz="0" izz="0"/>
    </inertial>
    <visual>
      <origin rpy="0 0 0" xyz="0 0 0"/>
      <geometry>
        <mesh filename="package://hsr_description/meshes/eye_hand_gripper/grisper_boby_link.STL"/>
      </geometry>
      <material name="">
        <color rgba="0.4 0.55 0.35 1"/>
      </material>
    </visual>
    <collision>
      <origin rpy="0 0 0" xyz="0 0 0"/>
      <geometry>
        <mesh filename="package://hsr_description/meshes/eye_hand_gripper/grisper_boby_link.STL"/>
      </geometry>
    </collision>
  </link>
  <joint name="grisper_boby_joint_1" type="fixed">
    <origin rpy="1.5708 1.3479E-15 1.3852E-15" xyz="0 -0.01 0.064"/>
    <parent link="gripper_base_link_1"/>
    <child link="grisper_boby_link_1"/>
    <axis xyz="0 0 0"/>
  </joint>
  <link name="right_finger_1_link_1">
    <inertial>
      <origin rpy="0 0 0" xyz="-2.92388038200531E-06 0.0168231601122346 0.0089790044607883"/>
      <mass value="0.00235032514171626"/>
      <inertia ixx="0" ixy="0" ixz="0" iyy="0" iyz="0" izz="0"/>
    </inertial>
    <visual>
      <origin rpy="0 0 0" xyz="0 0 0"/>
      <geometry>
        <mesh filename="package://hsr_description/meshes/eye_hand_gripper/right_finger_1_link.STL"/>
      </geometry>
      <material name="">
        <color rgba="0.4 0.55 0.35 1"/>
      </material>
    </visual>
    <collision>
      <origin rpy="0 0 0" xyz="0 0 0"/>
      <geometry>
        <mesh filename="package://hsr_description/meshes/eye_hand_gripper/right_finger_1_link.STL"/>
      </geometry>
    </collision>
  </link>
  <joint name="right_finger_1_joint_1" type="continuous">
    <origin rpy="0 0 -0.501740656078991" xyz="0.04 0.036 -0.019"/>
    <parent link="grisper_boby_link_1"/>
    <child link="right_finger_1_link_1"/>
    <axis xyz="0 0 1"/>
  </joint>
  <link name="right_finger_2_link_1">
    <inertial>
      <origin rpy="0 0 0" xyz="-0.0085798133911776 0.00661394976740351 0.00600000756322747"/>
      <mass value="0.00200167864656235"/>
      <inertia ixx="0" ixy="0" ixz="0" iyy="0" iyz="0" izz="0"/>
    </inertial>
    <visual>
      <origin rpy="0 0 0" xyz="0 0 0"/>
      <geometry>
        <mesh filename="package://hsr_description/meshes/eye_hand_gripper/right_finger_2_link.STL"/>
      </geometry>
      <material name="">
        <color rgba="0.4 0.55 0.35 1"/>
      </material>
    </visual>
    <collision>
      <origin rpy="0 0 0" xyz="0 0 0"/>
      <geometry>
        <mesh filename="package://hsr_description/meshes/eye_hand_gripper/right_finger_2_link.STL"/>
      </geometry>
    </collision>
  </link>
  <joint name="right_finger_2_joint_1" type="continuous">
    <origin rpy="0 0 0.501740656078991" xyz="0 0.042 0.00300000000000001"/>
    <parent link="right_finger_1_link_1"/>
    <child link="right_finger_2_link_1"/>
    <axis xyz="0 0 1"/>
  </joint>
  <link name="right_finger_end_link_1">
    <inertial>
      <origin rpy="0 0 0" xyz="-0.0181096606742553 0.00899999232533871 0.000419374358405108"/>
      <mass value="0.00169081070175499"/>
      <inertia ixx="0" ixy="0" ixz="0" iyy="0" iyz="0" izz="0"/>
    </inertial>
    <visual>
      <origin rpy="0 0 0" xyz="0 0 0"/>
      <geometry>
        <mesh filename="package://hsr_description/meshes/eye_hand_gripper/right_finger_end_link.STL"/>
      </geometry>
      <material name="">
        <color rgba="0.4 0.55 0.35 1"/>
      </material>
    </visual>
    <collision>
      <origin rpy="0 0 0" xyz="0 0 0"/>
      <geometry>
        <mesh filename="package://hsr_description/meshes/eye_hand_gripper/right_finger_end_link.STL"/>
      </geometry>
    </collision>
  </link>
  <joint name="right_finger_end_joint_1" type="fixed">
    <origin rpy="1.5707963267949 0 -1.5707963267949" xyz="-0.0145 -0.0035 -0.00300000000000001"/>
    <parent link="right_finger_2_link_1"/>
    <child link="right_finger_end_link_1"/>
    <axis xyz="0 0 0"/>
  </joint>
  <link name="left_finger_1_link_1">
    <inertial>
      <origin rpy="0 0 0" xyz="-2.92395601426965E-06 0.0168231599777492 0.00897900452955606"/>
      <mass value="0.0023503251697047"/>
      <inertia ixx="0" ixy="0" ixz="0" iyy="0" iyz="0" izz="0"/>
    </inertial>
    <visual>
      <origin rpy="0 0 0" xyz="0 0 0"/>
      <geometry>
        <mesh filename="package://hsr_description/meshes/eye_hand_gripper/left_finger_1_link.STL"/>
      </geometry>
      <material name="">
        <color rgba="0.4 0.55 0.35 1"/>
      </material>
    </visual>
    <collision>
      <origin rpy="0 0 0" xyz="0 0 0"/>
      <geometry>
        <mesh filename="package://hsr_description/meshes/eye_hand_gripper/left_finger_1_link.STL"/>
      </geometry>
    </collision>
  </link>
  <joint name="left_finger_1_joint_1" type="continuous">
    <origin rpy="0 0 0.501740656078991" xyz="-0.04 0.036 -0.019"/>
    <parent link="grisper_boby_link_1"/>
    <child link="left_finger_1_link_1"/>
    <axis xyz="0 0 1"/>
  </joint>
  <link name="left_finger_2_link_1">
    <inertial>
      <origin rpy="0 0 0" xyz="-0.00857981339117761 0.00661394976740348 0.00600000756322748"/>
      <mass value="0.00200167864656235"/>
      <inertia ixx="0" ixy="0" ixz="0" iyy="0" iyz="0" izz="0"/>
    </inertial>
    <visual>
      <origin rpy="0 0 0" xyz="0 0 0"/>
      <geometry>
        <mesh filename="package://hsr_description/meshes/eye_hand_gripper/left_finger_2_link.STL"/>
      </geometry>
      <material name="">
        <color rgba="0.4 0.55 0.35 1"/>
      </material>
    </visual>
    <collision>
      <origin rpy="0 0 0" xyz="0 0 0"/>
      <geometry>
        <mesh filename="package://hsr_description/meshes/eye_hand_gripper/left_finger_2_link.STL"/>
      </geometry>
    </collision>
  </link>
  <joint name="left_finger_2_joint_1" type="continuous">
    <origin rpy="3.14159265358979 0 2.6398519975108" xyz="0 0.0419999999999999 0.0149999999999995"/>
    <parent link="left_finger_1_link_1"/>
    <child link="left_finger_2_link_1"/>
    <axis xyz="0 0 1"/>
  </joint>
  <link name="left_finger_end_link_1">
    <inertial>
      <origin rpy="0 0 0" xyz="-0.0181096606742553 0.00899999232533872 0.000419374358405097"/>
      <mass value="0.00169081070175499"/>
      <inertia ixx="0" ixy="0" ixz="0" iyy="0" iyz="0" izz="0"/>
    </inertial>
    <visual>
      <origin rpy="0 0 0" xyz="0 0 0"/>
      <geometry>
        <mesh filename="package://hsr_description/meshes/eye_hand_gripper/left_finger_end_link.STL"/>
      </geometry>
      <material name="">
        <color rgba="0.4 0.55 0.35 1"/>
      </material>
    </visual>
    <collision>
      <origin rpy="0 0 0" xyz="0 0 0"/>
      <geometry>
        <mesh filename="package://hsr_description/meshes/eye_hand_gripper/left_finger_end_link.STL"/>
      </geometry>
    </collision>
  </link>
  <joint name="left_finger_end_joint_1" type="fixed">
    <origin rpy="1.5707963267949 8.67361737988403E-17 -1.5707963267949" xyz="-0.0144999999999999 -0.0035 -0.00299999999999996"/>
    <parent link="left_finger_2_link_1"/>
    <child link="left_finger_end_link_1"/>
    <axis xyz="0 0 0"/>
  </joint>
  <link name="pick_gripper_link_1">
    <visual>
      <origin rpy="0 0 0" xyz="0 0 0"/>
      <geometry>
        <box size="0.001 0.0005 0.0005"/>
      </geometry>
    </visual>
  </link>
  <transmission name="tran1_1">
    <type>transmission_interface/SimpleTransmission</type>
    <joint name="right_finger_1_joint_1">
      <hardwareInterface>PositionJointInterface</hardwareInterface>
    </joint>
    <actuator name="right_finger_1_motor_1">
      <hardwareInterface>PositionJointInterface</hardwareInterface>
      <mechanicalReduction>1</mechanicalReduction>
    </actuator>
  </transmission>
  <transmission name="tran2_1">
    <type>transmission_interface/SimpleTransmission</type>
    <joint name="right_finger_2_joint_1">
      <hardwareInterface>PositionJointInterface</hardwareInterface>
    </joint>
    <actuator name="right_finger_2_motor_1">
      <hardwareInterface>PositionJointInterface</hardwareInterface>
      <mechanicalReduction>1</mechanicalReduction>
    </actuator>
  </transmission>
  <transmission name="tran3_1">
    <type>transmission_interface/SimpleTransmission</type>
    <joint name="left_finger_1_joint_1">
      <hardwareInterface>PositionJointInterface</hardwareInterface>
    </joint>
    <actuator name="left_finger_1_motor_1">
      <hardwareInterface>PositionJointInterface</hardwareInterface>
      <mechanicalReduction>1</mechanicalReduction>
    </actuator>
  </transmission>
  <transmission name="tran4_1">
    <type>transmission_interface/SimpleTransmission</type>
    <joint name="left_finger_2_joint_1">
      <hardwareInterface>PositionJointInterface</hardwareInterface>
    </joint>
    <actuator name="left_finger_2_motor_1">
      <hardwareInterface>PositionJointInterface</hardwareInterface>
      <mechanicalReduction>1</mechanicalReduction>
    </actuator>
  </transmission>
  <!--///////////////////////////////////////////////////////////////////////-->
  <joint name="gripper_robot_joint_0" type="fixed">
    <parent link="link6"/>
    <child link="gripper_base_link_0"/>
    <origin rpy="0 0 3.14" xyz="0.0 0.0 0.0"/>
  </joint>
  <joint name="pick_gripper_joint_0" type="fixed">
    <origin rpy="0 -1.5708 1.5708" xyz="0 0.0 0.15"/>
    <axis xyz="0 0 1"/>
    <parent link="gripper_base_link_0"/>
    <child link="pick_gripper_link_0"/>
  </joint>
  <!--<//////////////////////////////////////////////////////////////////>-->
  <joint name="gripper_robot_joint_1" type="fixed">
    <parent link="R_link6"/>
    <child link="gripper_base_link_1"/>
    <origin rpy="0 0 3.14" xyz="0.0 0.0 0.0"/>
  </joint>
  <joint name="pick_gripper_joint_1" type="fixed">
    <origin rpy="0 -1.5708 1.5708" xyz="0 0.0 0.15"/>
    <axis xyz="0 0 1"/>
    <parent link="gripper_base_link_1"/>
    <child link="pick_gripper_link_1"/>
  </joint>
  <joint name="kinect_base_link_joint" type="fixed">
    <origin rpy=" 0 0 0" xyz="-0.5 -0.5 1"/>
    <parent link="base_link"/>
    <child link="camera_link"/>
  </joint>
</robot>

